  File "/home/runner/workspace/.pythonlibs/lib/python3.10/site-packages/sentry_sdk/integrations/threading.py", line 130, in run
    return _run_old_run_func()
  File "/home/runner/workspace/.pythonlibs/lib/python3.10/site-packages/sentry_sdk/integrations/threading.py", line 125, in _run_old_run_func
    reraise(*_capture_exception())
  File "/home/runner/workspace/.pythonlibs/lib/python3.10/site-packages/sentry_sdk/utils.py", line 1746, in reraise
    raise value
  File "/home/runner/workspace/.pythonlibs/lib/python3.10/site-packages/sentry_sdk/integrations/threading.py", line 123, in _run_old_run_func
    return old_run_func(self, *a, **kw)
  File "/nix/store/qlb1pg370bb647nj4dhc81y2jszvciz7-python3-3.10.16/lib/python3.10/threading.py", line 953, in run
    self._target(*self._args, **self._kwargs)
  File "/home/runner/workspace/.pythonlibs/lib/python3.10/site-packages/django/utils/autoreload.py", line 64, in wrapper
    fn(*args, **kwargs)
  File "/home/runner/workspace/.pythonlibs/lib/python3.10/site-packages/django/core/management/commands/runserver.py", line 134, in inner_run
    self.check(**check_kwargs)
  File "/home/runner/workspace/.pythonlibs/lib/python3.10/site-packages/django/core/management/base.py", line 492, in check
    all_issues = checks.run_checks(
  File "/home/runner/workspace/.pythonlibs/lib/python3.10/site-packages/django/core/checks/registry.py", line 89, in run_checks
    new_errors = check(app_configs=app_configs, databases=databases)
  File "/home/runner/workspace/.pythonlibs/lib/python3.10/site-packages/django/core/checks/urls.py", line 138, in check_custom_error_handlers
    path = getattr(resolver.urlconf_module, "handler%s" % status_code)
  File "/home/runner/workspace/.pythonlibs/lib/python3.10/site-packages/django/utils/functional.py", line 47, in __get__
    res = instance.__dict__[self.name] = self.func(instance)
  File "/home/runner/workspace/.pythonlibs/lib/python3.10/site-packages/django/urls/resolvers.py", line 711, in urlconf_module
    return import_module(self.urlconf_name)
  File "/nix/store/qlb1pg370bb647nj4dhc81y2jszvciz7-python3-3.10.16/lib/python3.10/importlib/__init__.py", line 126, in import_module
    return _bootstrap._gcd_import(name[level:], package, level)
  File "<frozen importlib._bootstrap>", line 1050, in _gcd_import
  File "<frozen importlib._bootstrap>", line 1027, in _find_and_load
  File "<frozen importlib._bootstrap>", line 1006, in _find_and_load_unlocked
  File "<frozen importlib._bootstrap>", line 688, in _load_unlocked
  File "<frozen importlib._bootstrap_external>", line 883, in exec_module
  File "<frozen importlib._bootstrap>", line 241, in _call_with_frames_removed
  File "/home/runner/workspace/nova_erp_total/urls.py", line 18, in <module>
    path('api/auth/', include('accounts.urls')),
  File "/home/runner/workspace/.pythonlibs/lib/python3.10/site-packages/django/urls/conf.py", line 39, in include
    urlconf_module = import_module(urlconf_module)
  File "/nix/store/qlb1pg370bb647nj4dhc81y2jszvciz7-python3-3.10.16/lib/python3.10/importlib/__init__.py", line 126, in import_module
    return _bootstrap._gcd_import(name[level:], package, level)
  File "<frozen importlib._bootstrap>", line 1050, in _gcd_import
  File "<frozen importlib._bootstrap>", line 1027, in _find_and_load
  File "<frozen importlib._bootstrap>", line 1006, in _find_and_load_unlocked
  File "<frozen importlib._bootstrap>", line 688, in _load_unlocked
  File "<frozen importlib._bootstrap_external>", line 883, in exec_module
  File "<frozen importlib._bootstrap>", line 241, in _call_with_frames_removed
  File "/home/runner/workspace/accounts/urls.py", line 8, in <module>
    from accounts.views.roles import RolViewSet
ImportError: cannot import name 'RolViewSet' from 'accounts.views.roles' (/home/runner/workspace/accounts/views/roles.py)
https://o4509617180311552.ingest.us.sentry.io:443 "POST /api/4509617183981568/envelope/ HTTP/1.1" 200 0
